{
 "metadata": {
  "language_info": {
   "codemirror_mode": {
    "name": "ipython",
    "version": 3
   },
   "file_extension": ".py",
   "mimetype": "text/x-python",
   "name": "python",
   "nbconvert_exporter": "python",
   "pygments_lexer": "ipython3",
   "version": "3.8.3-final"
  },
  "orig_nbformat": 2,
  "kernelspec": {
   "name": "python3",
   "display_name": "Python 3.8.3 64-bit",
   "metadata": {
    "interpreter": {
     "hash": "2db524e06e9f5f4ffedc911c917cb75e12dbc923643829bf417064a77eb14d37"
    }
   }
  }
 },
 "nbformat": 4,
 "nbformat_minor": 2,
 "cells": [
  {
   "source": [
    "<h1>Introducción a la estdística y al análisis de datos</h1>\n"
   ],
   "cell_type": "markdown",
   "metadata": {}
  },
  {
   "cell_type": "code",
   "execution_count": 10,
   "metadata": {},
   "outputs": [
    {
     "output_type": "error",
     "ename": "RuntimeError",
     "evalue": "The current Numpy installation ('C:\\\\Python38\\\\lib\\\\site-packages\\\\numpy\\\\__init__.py') fails to pass a sanity check due to a bug in the windows runtime. See this issue for more information: https://tinyurl.com/y3dm3h86",
     "traceback": [
      "\u001b[1;31m---------------------------------------------------------------------------\u001b[0m",
      "\u001b[1;31mRuntimeError\u001b[0m                              Traceback (most recent call last)",
      "\u001b[1;32m<ipython-input-10-dfe6e4abaa98>\u001b[0m in \u001b[0;36m<module>\u001b[1;34m\u001b[0m\n\u001b[0;32m      1\u001b[0m \u001b[1;31m#paquetes\u001b[0m\u001b[1;33m\u001b[0m\u001b[1;33m\u001b[0m\u001b[1;33m\u001b[0m\u001b[0m\n\u001b[1;32m----> 2\u001b[1;33m \u001b[1;32mimport\u001b[0m \u001b[0mnumpy\u001b[0m \u001b[1;32mas\u001b[0m \u001b[0mnp\u001b[0m\u001b[1;33m\u001b[0m\u001b[1;33m\u001b[0m\u001b[0m\n\u001b[0m",
      "\u001b[1;32mC:\\Python38\\lib\\site-packages\\numpy\\__init__.py\u001b[0m in \u001b[0;36m<module>\u001b[1;34m\u001b[0m\n\u001b[0;32m    303\u001b[0m \u001b[1;33m\u001b[0m\u001b[0m\n\u001b[0;32m    304\u001b[0m     \u001b[1;32mif\u001b[0m \u001b[0msys\u001b[0m\u001b[1;33m.\u001b[0m\u001b[0mplatform\u001b[0m \u001b[1;33m==\u001b[0m \u001b[1;34m\"win32\"\u001b[0m \u001b[1;32mand\u001b[0m \u001b[0msys\u001b[0m\u001b[1;33m.\u001b[0m\u001b[0mmaxsize\u001b[0m \u001b[1;33m>\u001b[0m \u001b[1;36m2\u001b[0m\u001b[1;33m**\u001b[0m\u001b[1;36m32\u001b[0m\u001b[1;33m:\u001b[0m\u001b[1;33m\u001b[0m\u001b[1;33m\u001b[0m\u001b[0m\n\u001b[1;32m--> 305\u001b[1;33m         \u001b[0m_win_os_check\u001b[0m\u001b[1;33m(\u001b[0m\u001b[1;33m)\u001b[0m\u001b[1;33m\u001b[0m\u001b[1;33m\u001b[0m\u001b[0m\n\u001b[0m\u001b[0;32m    306\u001b[0m \u001b[1;33m\u001b[0m\u001b[0m\n\u001b[0;32m    307\u001b[0m     \u001b[1;32mdel\u001b[0m \u001b[0m_win_os_check\u001b[0m\u001b[1;33m\u001b[0m\u001b[1;33m\u001b[0m\u001b[0m\n",
      "\u001b[1;32mC:\\Python38\\lib\\site-packages\\numpy\\__init__.py\u001b[0m in \u001b[0;36m_win_os_check\u001b[1;34m()\u001b[0m\n\u001b[0;32m    300\u001b[0m                    \u001b[1;34m\"See this issue for more information: \"\u001b[0m\u001b[1;33m\u001b[0m\u001b[1;33m\u001b[0m\u001b[0m\n\u001b[0;32m    301\u001b[0m                    \"https://tinyurl.com/y3dm3h86\")\n\u001b[1;32m--> 302\u001b[1;33m             \u001b[1;32mraise\u001b[0m \u001b[0mRuntimeError\u001b[0m\u001b[1;33m(\u001b[0m\u001b[0mmsg\u001b[0m\u001b[1;33m.\u001b[0m\u001b[0mformat\u001b[0m\u001b[1;33m(\u001b[0m\u001b[0m__file__\u001b[0m\u001b[1;33m)\u001b[0m\u001b[1;33m)\u001b[0m \u001b[1;32mfrom\u001b[0m \u001b[1;32mNone\u001b[0m\u001b[1;33m\u001b[0m\u001b[1;33m\u001b[0m\u001b[0m\n\u001b[0m\u001b[0;32m    303\u001b[0m \u001b[1;33m\u001b[0m\u001b[0m\n\u001b[0;32m    304\u001b[0m     \u001b[1;32mif\u001b[0m \u001b[0msys\u001b[0m\u001b[1;33m.\u001b[0m\u001b[0mplatform\u001b[0m \u001b[1;33m==\u001b[0m \u001b[1;34m\"win32\"\u001b[0m \u001b[1;32mand\u001b[0m \u001b[0msys\u001b[0m\u001b[1;33m.\u001b[0m\u001b[0mmaxsize\u001b[0m \u001b[1;33m>\u001b[0m \u001b[1;36m2\u001b[0m\u001b[1;33m**\u001b[0m\u001b[1;36m32\u001b[0m\u001b[1;33m:\u001b[0m\u001b[1;33m\u001b[0m\u001b[1;33m\u001b[0m\u001b[0m\n",
      "\u001b[1;31mRuntimeError\u001b[0m: The current Numpy installation ('C:\\\\Python38\\\\lib\\\\site-packages\\\\numpy\\\\__init__.py') fails to pass a sanity check due to a bug in the windows runtime. See this issue for more information: https://tinyurl.com/y3dm3h86"
     ]
    }
   ],
   "source": [
    "#paquetes\n",
    "import numpy as np"
   ]
  },
  {
   "source": [
    "<h2>Medidas de localización: la media y la mediana de una muestra</h2>\n",
    "<h3>Definición 1.1. (Media de la muestra)<h3>\n",
    "\n",
    "$$\\overline{x} = \\sum_{i=1}^n \\dfrac{x_i}{n} = \\dfrac{x_1 + x_2 + ... + x_n}{n}$$\n"
   ],
   "cell_type": "markdown",
   "metadata": {}
  },
  {
   "cell_type": "code",
   "execution_count": 2,
   "metadata": {},
   "outputs": [
    {
     "output_type": "execute_result",
     "data": {
      "text/plain": [
       "20.3125"
      ]
     },
     "metadata": {},
     "execution_count": 2
    }
   ],
   "source": [
    "def media(n):\n",
    "    sum = 0\n",
    "    for i in n:\n",
    "        sum += i\n",
    "    return sum/len(n)\n",
    "\n",
    "#ejemplos\n",
    "data=[2,3,9,5,16,14,21,5,0,21,8,95,78,43,3,2]\n",
    "media(data)"
   ]
  },
  {
   "cell_type": "code",
   "execution_count": 56,
   "metadata": {},
   "outputs": [
    {
     "output_type": "execute_result",
     "data": {
      "text/plain": [
       "20.3125"
      ]
     },
     "metadata": {},
     "execution_count": 56
    }
   ],
   "source": [
    "np.mean(data)"
   ]
  },
  {
   "source": [
    "<h3>Definición 1.2 (Mediana de la muestra)<h3>\n",
    "\n",
    "$$ \\tilde{x}= \\sum\\limits_{i=1}^{n} \\dfrac{x_i}{n} = \\dfrac{x_1+x_2+...+x_n}{n}$$"
   ],
   "cell_type": "markdown",
   "metadata": {}
  },
  {
   "cell_type": "code",
   "execution_count": 5,
   "metadata": {},
   "outputs": [
    {
     "output_type": "error",
     "ename": "NameError",
     "evalue": "name 'np' is not defined",
     "traceback": [
      "\u001b[1;31m---------------------------------------------------------------------------\u001b[0m",
      "\u001b[1;31mNameError\u001b[0m                                 Traceback (most recent call last)",
      "\u001b[1;32m<ipython-input-5-3904a8ddb077>\u001b[0m in \u001b[0;36m<module>\u001b[1;34m\u001b[0m\n\u001b[1;32m----> 1\u001b[1;33m \u001b[0mnp\u001b[0m\u001b[1;33m.\u001b[0m\u001b[0mmidian\u001b[0m\u001b[1;33m(\u001b[0m\u001b[0mdata\u001b[0m\u001b[1;33m)\u001b[0m\u001b[1;33m\u001b[0m\u001b[1;33m\u001b[0m\u001b[0m\n\u001b[0m",
      "\u001b[1;31mNameError\u001b[0m: name 'np' is not defined"
     ]
    }
   ],
   "source": [
    "np.midian(data)"
   ]
  },
  {
   "cell_type": "code",
   "execution_count": null,
   "metadata": {},
   "outputs": [],
   "source": []
  }
 ]
}